<?xml version="1.0"?>
<robot name="braccio_arm" xmlns:xacro="http://www.ros.org/wiki/xacro">
    
    
      <macro name="box_inertia" params="m x y z">
        <inertia  ixx="${m*(y*y+z*z)/12}" ixy = "0" ixz = "0"
                  iyy="${m*(x*x+z*z)/12}" iyz = "0"
                  izz="${m*(x*x+z*z)/12}" /> 
      </macro>    
      

    <material name="orange">
        <color rgba="0.57 0.17 0.0 1" />
    </material>
    <material name="white">
        <color rgba="0.8 0.8 0.8 1.0" />
    </material>
    <material name="black">
        <color rgba="0 0 0 0.50" />
    </material>      
    
  <link name="world"/>

  <joint name="fixed" type="fixed">
    <parent link="world"/>
    <child link="base_link"/>
  </joint>    
    
    <link name="base_link">
        <visual>
            <geometry>
                <cylinder length="0.01" radius=".053" />
            </geometry>
            <material name="black" />
            <origin rpy="0 0 0" xyz="0 0 0" />
        </visual>     
        <inertial>
            <origin xyz="0 0 0" rpy="0 0 0"/>
            <mass value="0.05"/>
            <box_inertia m="0.05" x="0.02" y="0.02" z="0.05"/>
        </inertial>
    </link>

    <link name="braccio_arm_base_link">
        <visual>
            <geometry>
                <mesh filename="package://braccio_arm_description/stl/braccio_base.stl" scale="0.001 0.001 0.001" />
            </geometry>
            <material name="orange" />
            <origin rpy="0 0 3.1416" xyz="0 0.004 0" />
        </visual>
        <inertial>
            <origin xyz="0 0 0" rpy="0 0 0"/>
            <mass value="0.05"/>
            <box_inertia m="0.05" x="0.02" y="0.02" z="0.05"/>
        </inertial>        
    </link>

    <link name="shoulder_link">
        <visual>
            <geometry>
                <mesh filename="package://braccio_arm_description/stl/braccio_shoulder.stl" scale="0.001 0.001 0.001" />
            </geometry>
            <material name="orange" />
            <origin rpy="0 0 0" xyz="-0.0045 0.0055 -0.026" />
        </visual>
        <inertial>
            <origin xyz="0 0 0" rpy="0 0 0"/>
            <mass value="0.05"/>
            <box_inertia m="0.05" x="0.02" y="0.02" z="0.05"/>
        </inertial>        
    </link>

    <link name="elbow_link">
        <visual>
            <geometry>
                <mesh filename="package://braccio_arm_description/stl/braccio_elbow.stl" scale="0.001 0.001 0.001" />
            </geometry>
            <material name="orange" />
            <origin rpy="0 0 0" xyz="-0.0045 0.005 -0.025" />
        </visual>
        <inertial>
            <origin xyz="0 0 0" rpy="0 0 0"/>
            <mass value="0.05"/>
            <box_inertia m="0.05" x="0.02" y="0.02" z="0.05"/>
        </inertial>        
    </link>

    <link name="wrist_pitch_link">
        <visual>
            <geometry>
                <mesh filename="package://braccio_arm_description/stl/braccio_wrist_pitch.stl" scale="0.001 0.001 0.001" />
            </geometry>
            <material name="orange" />
            <origin rpy="0 0 0" xyz="0.003 -0.0004 -0.024" />
        </visual>
        <inertial>
            <origin xyz="0 0 0" rpy="0 0 0"/>
            <mass value="0.05"/>
            <box_inertia m="0.05" x="0.02" y="0.02" z="0.05"/>
        </inertial>        
    </link>

    <link name="wrist_roll_link">
        <visual>
            <geometry>
                <mesh filename="package://braccio_arm_description/stl/braccio_wrist_roll.stl" scale="0.001 0.001 0.001" />
            </geometry>
            <material name="white" />
            <origin rpy="0 0 0" xyz="0.006 0 0.0" />
        </visual>
        <inertial>
            <origin xyz="0 0 0" rpy="0 0 0"/>
            <mass value="0.05"/>
            <box_inertia m="0.05" x="0.02" y="0.02" z="0.05"/>
        </inertial>        
    </link>

    <link name="left_gripper_link">
        <visual>
            <geometry>
                <mesh filename="package://braccio_arm_description/stl/braccio_left_gripper.stl" scale="0.001 0.001 0.001" />
            </geometry>
            <material name="white" />
            <origin rpy="0 1.5708 0" xyz="0 -0.007 0" />
        </visual>
        <visual>
            <geometry>
                <mesh filename="package://braccio_arm_description/stl/braccio_left_gripper.stl" scale="0.001 0.001 0.001" />
            </geometry>
            <material name="white" />
            <origin rpy="0 1.5708 0" xyz="0 -0.017 0" />
        </visual>        
        <inertial>
            <origin xyz="0 0 0" rpy="0 0 0"/>
            <mass value="0.01"/>
            <box_inertia m="0.01" x="0.02" y="0.02" z="0.05"/>
        </inertial>        
    </link>

    <link name="right_gripper_link">
        <collision>
            <geometry>
                <cylinder length="0.01" radius=".053" />
            </geometry>
            <material name="black" />
            <origin rpy="0 0 0" xyz="0 0 0" />
        </collision>          
        <visual>
            <geometry>
                <mesh filename="package://braccio_arm_description/stl/braccio_right_gripper.stl" scale="0.001 0.001 0.001" />
            </geometry>
            <material name="white" />
            <origin rpy="0 1.5708 0" xyz="0 -0.017 0.010" />
        </visual>
        <visual>
            <geometry>
                <mesh filename="package://braccio_arm_description/stl/braccio_right_gripper.stl" scale="0.001 0.001 0.001" />
            </geometry>
            <material name="white" />
            <origin rpy="0 1.5708 0" xyz="0 -0.007 0.010" />
        </visual>        
        <inertial>
            <origin xyz="0 0 0" rpy="0 0 0"/>
            <mass value="0.01"/>
            <box_inertia m="0.01" x="0.02" y="0.02" z="0.05"/>
        </inertial>        
    </link>

    <joint name="base_joint" type="revolute">
        <axis xyz="0 0 1" />
        <limit effort="1000.0" lower="0.0" upper="3.1416" velocity="1.0" />
        <origin rpy="0 0 0" xyz="0 0 0" />
        <parent link="base_link" />
        <child link="braccio_arm_base_link" />
    </joint>

    <joint name="shoulder_joint" type="revolute">
        <axis xyz="1 0 0" />
        <limit effort="1000.0" lower="0.2618" upper="2.8798" velocity="1.0" />
        <origin rpy="-1.5708 0 0" xyz="0 -.002 0.072" />
        <parent link="braccio_arm_base_link" />
        <child link="shoulder_link" />
    </joint>

    <joint name="elbow_joint" type="revolute">
        <axis xyz="1 0 0" />
        <limit effort="1000.0" lower="0" upper="3.1416" velocity="1.0" />
        <origin rpy="-1.5708 0 0" xyz="0 0 0.125" />
        <parent link="shoulder_link" />
        <child link="elbow_link" />
    </joint>

    <joint name="wrist_pitch_joint" type="revolute">
        <axis xyz="1 0 0" />
        <limit effort="1000.0" lower="0" upper="3.1416" velocity="1.0" />
        <origin rpy="-1.5708 0 0" xyz="0 0 0.125" />
        <parent link="elbow_link" />
        <child link="wrist_pitch_link" />
    </joint>

    <joint name="wrist_roll_joint" type="revolute">
        <axis xyz="0 0 -1" />
        <limit effort="1000.0" lower="0.0" upper="3.1416" velocity="1.0" />
        <origin rpy="0 0 1.5708" xyz="0 0.0 0.06" />
        <parent link="wrist_pitch_link" />
        <child link="wrist_roll_link" />
    </joint>

    <joint name="gripper_joint" type="revolute">
        <axis xyz="0 -1 0" />
        <limit effort="1000.0" lower="0.1750" upper="1.2741" velocity="1.0" />
        <origin rpy="0 -0.2967 0" xyz="0.010 0 0.03" />
        <parent link="wrist_roll_link" />
        <child link="right_gripper_link" />
    </joint>

    <joint name="sub_gripper_joint" type="revolute">
        <axis xyz="0 1 0" />
        <mimic joint="gripper_joint" />
        <limit effort="1000.0" lower="0.1750" upper="1.2741" velocity="1.0" />
        <origin rpy="0 3.4383 0" xyz="-0.010 0 0.03" />
        <parent link="wrist_roll_link" />
        <child link="left_gripper_link" />
    </joint>

    
    <xacro:include filename="$(find braccio_arm_description)/urdf/braccio_arm.gazebo" />
    
</robot>
